Workbook

Sheet Historicals
A1: Microsoft Corporation (MSFT) — Historical Financial Summary
A2: Source: SEC EDGAR Form 10-K | FY2022–FY2024 | Fiscal Year End: June 30 | $ in Millions
B4: FY2022 | C4: FY2023 | D4: FY2024
A5: INCOME STATEMENT ($M)
A6: Revenue | B6: 198270 | C6: 211915 | D6: 245122
A7: Cost of Revenue | B7: 62650 | C7: 65863 | D7: 74114
A8: Gross Profit | B8: =B6-B7 -> 135620 | C8: =C6-C7 -> 146052 | D8: =D6-D7 -> 171008
A9: Gross Margin % | B9: =B8/B6 -> 0.68401674 | C9: =C8/C6 -> 0.68920086 | D9: =D8/D6 -> 0.69764444
A11: Research & Development | B11: 24512 | C11: 27195 | D11: 29510
A12: Sales & Marketing | B12: 21825 | C12: 22759 | D12: 24456
A13: General & Administrative | B13: 5900 | C13: 7575 | D13: 7609
A14: Total Operating Expenses | B14: =B11+B12+B13 -> 52237 | C14: =C11+C12+C13 -> 57529 | D14: =D11+D12+D13 -> 61575
A16: EBIT (Operating Income) | B16: 83383 | C16: 88523 | D16: 109433
A17: EBIT Margin % | B17: =B16/B6 -> 0.42055278 | C17: =C16/C6 -> 0.41772881 | D17: =D16/D6 -> 0.446443
A19: Income Before Tax | B19: 83716 | C19: 89311 | D19: 107787
A20: Provision for Income Taxes | B20: 10978 | C20: 16950 | D20: 19651
A21: Effective Tax Rate | B21: =B20/B19 -> 0.13113383 | C21: =C20/C19 -> 0.18978625 | D21: =D20/D19 -> 0.18231327
A23: NOPAT (EBIT × (1 - Tax Rate)) | B23: =B16*(1-B21) -> 72448.668 | C23: =C16*(1-C21) -> 71722.552 | D23: =D16*(1-D21) -> 89481.912
A25: FREE CASH FLOW BRIDGE ($M)
A26: NOPAT | B26: =B23 -> 72448.668 | C26: =C23 -> 71722.552 | D26: =D23 -> 89481.912
A27: (+) Depreciation & Amortization | B27: 14460 | C27: 13861 | D27: 22287
A28: (-) Capital Expenditures | B28: 23886 | C28: 28107 | D28: 44477
A29: (-) Change in Net Working Capital | B29: -1730 | C29: -250 | D29: -6205
A31: Unlevered Free Cash Flow | B31: =B26+B27-B28-B29 -> 64752.668 | C31: =C26+C27-C28-C29 -> 57726.552 | D31: =D26+D27-D28-D29 -> 73496.912
A32: UFCF Margin % | B32: =B31/B6 -> 0.32658833 | C32: =C31/C6 -> 0.27240427 | D32: =D31/D6 -> 0.29983809

Sheet Assumptions
A1: SCENARIO SELECTOR
A2: Active Scenario: | B2: Base Case
A4: SCENARIO INPUTS TABLE
A5: Parameter | B5: Bear Case | C5: Base Case | D5: Bull Case | E5: Active Value
A6: FY2025 Revenue Growth | B6: 0.1 | C6: 0.15 | D6: 0.18 | E6: =CHOOSE(MATCH($B$2,{"Bear Case","Base Case","Bull Case"},0),B6,C6,D6) -> 0.15
A7: FY2026 Revenue Growth | B7: 0.09 | C7: 0.14 | D7: 0.17 | E7: =CHOOSE(MATCH($B$2,{"Bear Case","Base Case","Bull Case"},0),B7,C7,D7) -> 0.14
A8: FY2027 Revenue Growth | B8: 0.08 | C8: 0.13 | D8: 0.15 | E8: =CHOOSE(MATCH($B$2,{"Bear Case","Base Case","Bull Case"},0),B8,C8,D8) -> 0.13
A9: FY2028 Revenue Growth | B9: 0.07 | C9: 0.12 | D9: 0.13 | E9: =CHOOSE(MATCH($B$2,{"Bear Case","Base Case","Bull Case"},0),B9,C9,D9) -> 0.12
A10: FY2029 Revenue Growth | B10: 0.06 | C10: 0.11 | D10: 0.11 | E10: =CHOOSE(MATCH($B$2,{"Bear Case","Base Case","Bull Case"},0),B10,C10,D10) -> 0.11
A11: EBIT Margin % | B11: 0.42 | C11: 0.45 | D11: 0.48 | E11: =CHOOSE(MATCH($B$2,{"Bear Case","Base Case","Bull Case"},0),B11,C11,D11) -> 0.45
A12: WACC | B12: 0.11 | C12: 0.09 | D12: 0.075 | E12: =CHOOSE(MATCH($B$2,{"Bear Case","Base Case","Bull Case"},0),B12,C12,D12) -> 0.09
A13: Terminal Growth Rate | B13: 0.015 | C13: 0.03 | D13: 0.035 | E13: =CHOOSE(MATCH($B$2,{"Bear Case","Base Case","Bull Case"},0),B13,C13,D13) -> 0.03
A14: ↑ Change scenario above — all model outputs update automatically
A17: Microsoft Corporation (MSFT) — DCF Model Assumptions
A18: All assumptions are hardcoded inputs (blue font) — editable for scenario analysis
A20: PROJECTION PERIOD
A21: Parameter | B21: Value | C21: Note | D21: Analyst Rationale
A22: Projection Period (Years) | B22: 5 | C22: FY2025–FY2029 | D22: Standard 5-year explicit projection horizon for mature large-cap DCF
A24: REVENUE GROWTH RATES
A25: Year | B25: Growth Rate | D25: Analyst Rationale
A26: FY2025 | B26: =E6 -> 0.15 | C26: Year 1 | D26: AI-driven cloud + Copilot monetization; consistent w/ MSFT FY24A revenue growth of 16%
A27: FY2026 | B27: =E7 -> 0.14 | C27: Year 2 | D27: Slight deceleration as AI tailwinds mature; Azure growth normalizes toward 30-35%
A28: FY2027 | B28: =E8 -> 0.13 | C28: Year 3 | D28: Continued enterprise AI adoption; on-prem to cloud migration sustains growth
A29: FY2028 | B29: =E9 -> 0.12 | C29: Year 4 | D29: Broader market penetration; growth moderates as base expands
A30: FY2029 | B30: =E10 -> 0.11 | C30: Year 5 | D30: Approaching long-run sustainable growth; converging toward terminal rate
A32: MARGIN ASSUMPTIONS
A33: Assumption | B33: Rate | D33: Analyst Rationale
A34: Gross Margin % | B34: 0.7 | C34: % of Revenue | D34: FY24A was 69.8%; 70% assumes modest improvement as cloud mix grows (higher-margin)
A35: EBIT Margin % | B35: =E11 -> 0.45 | C35: % of Revenue | D35: FY24A was 44.6%; 45% reflects continued operating leverage + AI efficiency gains
A36: Tax Rate | B36: 0.18 | C36: Effective rate | D36: User-specified 18%; vs. FY24A effective rate of 18.2% — consistent with recent trend
A37: D&A as % of Revenue | B37: 0.04 | C37: % of Revenue | D37: FY24A D&A was 9.1% (cloud infra-heavy year); 4% reflects normalized steady-state D&A
A38: Capex as % of Revenue | B38: 0.05 | C38: % of Revenue | D38: FY24A CapEx was 18.1% (AI buildout cycle); 5% assumes moderation post-peak spend
A39: Change in NWC as % of Revenue | B39: 0.01 | C39: % of Revenue (use of cash) | D39: MSFT historically runs negative NWC delta (deferred revenue growth); 1% use-of-cash conservative
A42: WACC & TERMINAL VALUE
A43: Parameter | B43: Value | D43: Analyst Rationale
A44: WACC | B44: =E12 -> 0.09 | C44: Weighted Average Cost of Capital | D44: 9% reflects large-cap tech WACC; ~3.8-4.4% risk-free rate + beta-adjusted ERP for MSFT (~0.9 beta)
A45: Terminal Growth Rate | B45: =E13 -> 0.03 | C45: Gordon Growth Model (perpetuity) | D45: 3.0% equals long-run nominal GDP growth; reasonable for a global enterprise software platform
A48: EQUITY BRIDGE INPUTS
A49: Parameter | B49: Value | C49: Note | D49: Analyst Rationale
A50: Shares Outstanding (M) | B50: 7430 | C50: Diluted shares as of FY2024 | D50: FY2024 diluted weighted-average shares per 10-K
...

Sheet Projections
A1: Microsoft Corporation (MSFT) — 5-Year Financial Projections
A2: All projections driven by Assumptions sheet — no hardcoded values | $ in Millions
B4: FY2024A | C4: FY2025E | D4: FY2026E | E4: FY2027E | F4: FY2028E | G4: FY2029E
A5: INCOME STATEMENT ($M)
A6: Revenue | B6: =Historicals!D6 -> 245122 | C6: =B6*(1+Assumptions!$B$26) -> 281890.3 | D6: =C6*(1+Assumptions!$B$27) -> 321354.94 | E6: =D6*(1+Assumptions!$B$28) -> 363131.08 | F6: =E6*(1+Assumptions!$B$29) -> 406706.81 | G6: =F6*(1+Assumptions!$B$30) -> 451444.56
A7: Revenue Growth % | C7: =C6/B6-1 -> 0.15 | D7: =D6/C6-1 -> 0.14 | E7: =E6/D6-1 -> 0.13 | F7: =F6/E6-1 -> 0.12 | G7: =G6/F6-1 -> 0.11
A9: Gross Profit | B9: =Historicals!D8 -> 171008 | C9: =C6*Assumptions!$B$34 -> 197323.21 | D9: =D6*Assumptions!$B$34 -> 224948.46 | E9: =E6*Assumptions!$B$34 -> 254191.76 | F9: =F6*Assumptions!$B$34 -> 284694.77 | G9: =G6*Assumptions!$B$34 -> 316011.19
A10: Gross Margin % | B10: =Historicals!D9 -> 0.69764444 | C10: =C9/C6 -> 0.7 | D10: =D9/D6 -> 0.7 | E10: =E9/E6 -> 0.7 | F10: =F9/F6 -> 0.7 | G10: =G9/G6 -> 0.7
A12: R&D | B12: =Historicals!D11 -> 29510 | C12: =C6*(Historicals!$D$11/Historicals!$D$6)*(1-0.005*0) -> 33936.5 | D12: =D6*(Historicals!$D$11/Historicals!$D$6)*(1-0.005*1) -> 38494.172 | E12: =E6*(Historicals!$D$11/Historicals!$D$6)*(1-0.005*2) -> 43279.829 | F12: =F6*(Historicals!$D$11/Historicals!$D$6)*(1-0.005*3) -> 48228.594 | G12: =G6*(Historicals!$D$11/Historicals!$D$6)*(1-0.005*4) -> 53261.994
A13: Sales & Marketing | B13: =Historicals!D12 -> 24456 | C13: =C6*(Historicals!$D$12/Historicals!$D$6)*(1-0.005*0) -> 28124.4 | D13: =D6*(Historicals!$D$12/Historicals!$D$6)*(1-0.005*1) -> 31901.507 | E13: =E6*(Historicals!$D$12/Historicals!$D$6)*(1-0.005*2) -> 35867.554 | F13: =F6*(Historicals!$D$12/Historicals!$D$6)*(1-0.005*3) -> 39968.773 | G13: =G6*(Historicals!$D$12/Historicals!$D$6)*(1-0.005*4) -> 44140.133
A14: G&A | B14: =Historicals!D13 -> 7609 | C14: =C6*(Historicals!$D$13/Historicals!$D$6)*(1-0.003*0) -> 8750.35 | D14: =D6*(Historicals!$D$13/Historicals!$D$6)*(1-0.003*1) -> 9945.4728 | E14: =E6*(Historicals!$D$13/Historicals!$D$6)*(1-0.003*2) -> 11204.568 | F14: =F6*(Historicals!$D$13/Historicals!$D$6)*(1-0.003*3) -> 12511.241 | G14: =G6*(Historicals!$D$13/Historicals!$D$6)*(1-0.003*4) -> 13845.437
A15: Total OpEx | B15: =Historicals!D14 -> 61575 | C15: =C12+C13+C14 -> 70811.25 | D15: =D12+D13+D14 -> 80341.152 | E15: =E12+E13+E14 -> 90351.951 | F15: =F12+F13+F14 -> 100708.61 | G15: =G12+G13+G14 -> 111247.56
A17: EBIT | B17: =Historicals!D16 -> 109433 | C17: =C6*Assumptions!$B$35 -> 126850.63 | D17: =D6*Assumptions!$B$35 -> 144609.72 | E17: =E6*Assumptions!$B$35 -> 163408.99 | F17: =F6*Assumptions!$B$35 -> 183018.07 | G17: =G6*Assumptions!$B$35 -> 203150.05
A18: EBIT Margin % | B18: =Historicals!D17 -> 0.446443 | C18: =C17/C6 -> 0.45 | D18: =D17/D6 -> 0.45 | E18: =E17/E6 -> 0.45 | F18: =F17/F6 -> 0.45 | G18: =G17/G6 -> 0.45
A20: Taxes | B20: =Historicals!D20 -> 19651 | C20: =C17*Assumptions!$B$36 -> 22833.114 | D20: =D17*Assumptions!$B$36 -> 26029.75 | E20: =E17*Assumptions!$B$36 -> 29413.618 | F20: =F17*Assumptions!$B$36 -> 32943.252 | G20: =G17*Assumptions!$B$36 -> 36567.01
A21: Effective Tax Rate | B21: =Historicals!D21 -> 0.18231327 | C21: =C20/C17 -> 0.18 | D21: =D20/D17 -> 0.18 | E21: =E20/E17 -> 0.18 | F21: =F20/F17 -> 0.18 | G21: =G20/G17 -> 0.18
A23: NOPAT | B23: =Historicals!D23 -> 89481.912 | C23: =C17-C20 -> 104017.52 | D23: =D17-D20 -> 118579.97 | E23: =E17-E20 -> 133995.37 | F23: =F17-F20 -> 150074.81 | G23: =G17-G20 -> 166583.04
A25: FREE CASH FLOW BRIDGE ($M)
A26: NOPAT | B26: =B23 -> 89481.912 | C26: =C23 -> 104017.52 | D26: =D23 -> 118579.97 | E26: =E23 -> 133995.37 | F26: =F23 -> 150074.81 | G26: =G23 -> 166583.04
A27: (+) Depreciation & Amortization | B27: 22287 | C27: =C6*Assumptions!$B$37 -> 11275.612 | D27: =D6*Assumptions!$B$37 -> 12854.198 | E27: =E6*Assumptions!$B$37 -> 14525.243 | F27: =F6*Assumptions!$B$37 -> 16268.273 | G27: =G6*Assumptions!$B$37 -> 18057.783
A28: (-) Capital Expenditures | B28: 44477 | C28: =C6*Assumptions!$B$38 -> 14094.515 | D28: =D6*Assumptions!$B$38 -> 16067.747 | E28: =E6*Assumptions!$B$38 -> 18156.554 | F28: =F6*Assumptions!$B$38 -> 20335.341 | G28: =G6*Assumptions!$B$38 -> 22572.228
A29: (-) Change in Net Working Capital | B29: -6205 | C29: =(C6-B6)*Assumptions!$B$39 -> 367.683 | D29: =(D6-C6)*Assumptions!$B$39 -> 394.64642 | E29: =(E6-D6)*Assumptions!$B$39 -> 417.76142 | F29: =(F6-E6)*Assumptions!$B$39 -> 435.7573 | G29: =(G6-F6)*Assumptions!$B$39 -> 447.3775
A31: Unlevered Free Cash Flow (UFCF) | B31: =B26+B27-B28-B29 -> 73496.912 | C31: =C26+C27-C28-C29 -> 100830.93 | D31: =D26+D27-D28-D29 -> 114971.78 | E31: =E26+E27-E28-E29 -> 129946.3 | F31: =F26+F27-F28-F29 -> 145571.99 | G31: =G26+G27-G28-G29 -> 161621.22
A32: UFCF Margin % | B32: =B31/B6 -> 0.29983809 | C32: =C31/C6 -> 0.35769565 | D32: =D31/D6 -> 0.35777193 | E32: =E31/E6 -> 0.35784956 | F32: =F31/F6 -> 0.35792857 | G32: =G31/G6 -> 0.35800901

Sheet DCF Valuation
A1: Microsoft Corporation (MSFT) — Discounted Cash Flow Valuation
A2: Mid-year convention | Gordon Growth Model terminal value | $ in Millions
A4: STEP 1 — PROJECTED FREE CASH FLOWS & DISCOUNT FACTORS
B5: FY2025E | C5: FY2026E | D5: FY2027E | E5: FY2028E | F5: FY2029E
A6: Unlevered FCF ($M) | B6: =Projections!C31 -> 100830.93 | C6: =Projections!D31 -> 114971.78 | D6: =Projections!E31 -> 129946.3 | E6: =Projections!F31 -> 145571.99 | F6: =Projections!G31 -> 161621.22 | G6: Total
A7: Discount Period (mid-year) | B7: 0.5 | C7: 1.5 | D7: 2.5 | E7: 3.5 | F7: 4.5
A8: Discount Factor (1/(1+WACC)^t) | B8: =1/(1+Assumptions!$B$44)^B7 -> 0.95782629 | C8: =1/(1+Assumptions!$B$44)^C7 -> 0.87873971 | D8: =1/(1+Assumptions!$B$44)^D7 -> 0.80618322 | E8: =1/(1+Assumptions!$B$44)^E7 -> 0.73961763 | F8: =1/(1+Assumptions!$B$44)^F7 -> 0.67854829
A9: PV of FCF ($M) | B9: =B6*B8 -> 96578.52 | C9: =C6*C8 -> 101030.27 | D9: =D6*D8 -> 104760.53 | E9: =E6*E8 -> 107667.61 | F9: =F6*F8 -> 109667.8 | G9: =SUM(B9:F9) -> 519704.72
A12: STEP 2 — TERMINAL VALUE (Gordon Growth Model)
A13: Terminal Year FCF ($M) — FY2029E | B13: =Projections!G31 -> 161621.22
A14: Terminal Growth Rate (g) | B14: =Assumptions!$B$45 -> 0.03
A15: WACC | B15: =Assumptions!$B$44 -> 0.09
A16: Terminal Value = FCF x (1+g) / (WACC - g) | B16: =B13*(1+B14)/(B15-B14) -> 2774497.6
A17: Terminal Value Discount Period | B17: 4.5
A18: Discount Factor | B18: =1/(1+B15)^B17 -> 0.67854829
A19: PV of Terminal Value ($M) | B19: =B16*B18 -> 1882630.6
A22: STEP 3 - ENTERPRISE VALUE
A23: (+) Sum of PV of FCFs ($M) | B23: =G9 -> 519704.72
A24: (+) PV of Terminal Value ($M) | B24: =B19 -> 1882630.6
A25: Enterprise Value ($M) | B25: =B23+B24 -> 2402335.3
A26: % of EV from Terminal Value | B26: =B24/B25 -> 0.78366687
A28: STEP 4 — EQUITY VALUE & PRICE PER SHARE
A29: Enterprise Value ($M) | B29: =B25 -> 2402335.3
A30: Net Debt ($M) [negative = net cash] | B30: =Assumptions!$B$51 -> -26000
A31: Equity Value ($M) | B31: =B29-B30 -> 2428335.3
A33: Shares Outstanding (M) | B33: =Assumptions!$B$50 -> 7430
A34: Implied Price Per Share | B34: =B31/B33 -> 326.82844
A35: Current Share Price | B35: =Assumptions!$B$52 -> 420
A36: Implied Upside / (Downside) | B36: =B34/B35-1 -> -0.22183704
A37: Verdict | B37: =IF(B34>B35*1.1,"BUY",IF(B34>=B35*0.9,"HOLD","SELL")) -> SELL
A40: STEP 0 — WACC CALCULATION (CAPM Methodology)
A41: COST OF EQUITY (CAPM)
A42: Risk-Free Rate (10Y US Treasury Yield) | B42: 0.0438
A43: Equity Risk Premium (ERP) | B43: 0.055
A44: Beta (5-Year Monthly vs. S&P 500) | B44: 0.9
A45: Cost of Equity = Rf + β × ERP | B45: =B42+B44*B43 -> 0.0933
A47: COST OF DEBT
A48: Pre-Tax Cost of Debt | B48: 0.038
A49: Tax Rate (from Assumptions) | B49: =Assumptions!$B$36 -> 0.18
A50: After-Tax Cost of Debt = Kd × (1 - Tax Rate) | B50: =B48*(1-B49) -> 0.03116
...

Sheet Sensitivity
A1: Microsoft Corporation (MSFT) — DCF Sensitivity Analysis
A2: Each cell recalculates the full DCF for that WACC × Terminal Growth Rate combination | $ in Millions
A4: TABLE 1 — IMPLIED SHARE PRICE vs. WACC & TERMINAL GROWTH RATE
A5: WACC \ TGR | B5: 0.015 | C5: 0.02 | D5: 0.025 | E5: 0.03 | F5: 0.035 | G5: 0.04 | H5: 0.045 | I5: ← Terminal Growth Rate →
A6: 0.07 | B6: =(((((Historicals!$D$6*(1+Assumptions!$B$26))*(Assumptions!$B$35*(1-Assumptions!$B$36)+Assumptions!$B$37-Assumptions!$B$38)-((Historicals!$D$6*(1+Assumptions!$B$26))-Historicals!$D$6)*Assumptions!$B$39)/(1+$A6)^0.5)+((((Historicals!$D$6*(1+Assumptions!$B$26))*(1+Assumptions!$B$27))*(Assumptions!$B$35*(1-Assumptions!$B$36)+Assumptions!$B$37-Assumptions!$B$38)-(((Historicals!$D$6*(1+Assumptions!$B$26))*(1+Assumptions!$B$27))-(Historicals!$D$6*(1+Assumptions!$B$26)))*Assumptions!$B$39)/(1+$A6)^1.5)+(((((Historicals!$D$6*(1+Assumptions!$B$26))*(1+Assumptions!$B$27))*(1+Assumptions!$B$28))*(Assumptions!$B$35*(1-Assumptions!$B$36)+Assumptions!$B$37-Assumptions!$B$38)-((((Historicals!$D$6*(1+Assumptions!$B$26))*(1+Assumptions!$B$27))*(1+Assumptions!$B$28))-((Historicals!$D$6*(1+Assumptions!$B$26))*(1+Assumptions!$B$27)))*Assumptions!$B$39)/(1+$A6)^2.5)+((((((Historicals!$D$6*(1+Assumptions!$B$26))*(1+Assumptions!$B$27))*(1+Assumptions!$B$28))*(1+Assumptions!$B$29))*(Assumptions!$B$35*(1-Assumptions!$B$36)+Assumptions!$B$37-Assumptions!$B$38)-(((((Historicals!$D$6*(1+Assumptions!$B$26))*(1+Assumptions!$B$27))*(1+Assumptions!$B$28))*(1+Assumptions!$B$29))-(((Historicals!$D$6*(1+Assumptions!$B$26))*(1+Assumptions!$B$27))*(1+Assumptions!$B$28)))*Assumptions!$B$39)/(1+$A6)^3.5)+(((((((Historicals!$D$6*(1+Assumptions!$B$26))*(1+Assumptions!$B$27))*(1+Assumptions!$B$28))*(1+Assumptions!$B$29))*(1+Assumptions!$B$30))*(Assumptions!$B$35*(1-Assumptions!$B$36)+Assumptions!$B$37-Assumptions!$B$38)-((((((Historicals!$D$6*(1+Assumptions!$B$26))*(1+Assumptions!$B$27))*(1+Assumptions!$B$28))*(1+Assumptions!$B$29))*(1+Assumptions!$B$30))-((((Historicals!$D$6*(1+Assumptions!$B$26))*(1+Assumptions!$B$27))*(1+Assumptions!$B$28))*(1+Assumptions!$B$29)))*Assumptions!$B$39)/(1+$A6)^4.5)+((((((((Historicals!$D$6*(1+Assumptions!$B$26))*(1+Assumptions!$B$27))*(1+Assumptions!$B$28))*(1+Assumptions!$B$29))*(1+Assumptions!$B$30))*(Assumptions!$B$35*(1-Assumptions!$B$36)+Assumptions!$B$37-Assumptions!$B$38)-((((((Historicals!$D$6*(1+Assumptions!$B$26))*(1+Assumptions!$B$27))*(1+Assumptions!$B$28))*(1+Assumptions!$B$29))*(1+Assumptions!$B$30))-((((Historicals!$D$6*(1+Assumptions!$B$26))*(1+Assumptions!$B$27))*(1+Assumptions!$B$28))*(1+Assumptions!$B$29)))*Assumptions!$B$39)*(1+B$5)/($A6-B$5))/(1+$A6)^4.5))-Assumptions!$B$51)/Assumptions!$B$50 -> 372.93553 | C6: =(((((Historicals!$D$6*(1+Assumptions!$B$26))*(Assumptions!$B$35*(1-Assumptions!$B$36)+Assumptions!$B$37-Assumptions!$B$38)-((Historicals!$D$6*(1+Assumptions!$B$26))-Historicals!$D$6)*Assumptions!$B$39)/(1+$A6)^0.5)+((((Historicals!$D$6*(1+Assumptions!$B$26))*(1+Assumptions!$B$27))*(Assumptions!$B$35*(1-Assumptions!$B$36)+Assumptions!$B$37-Assumptions!$B$38)-(((Historicals!$D$6*(1+Assumptions!$B$26))*(1+Assumptions!$B$27))-(Historicals!$D$6*(1+Assumptions!$B$26)))*Assumptions!$B$39)/(1+$A6)^1.5)+(((((Historicals!$D$6*(1+Assumptions!$B$26))*(1+Assumptions!$B$27))*(1+Assumptions!$B$28))*(Assumptions!$B$35*(1-Assumptions!$B$36)+Assumptions!$B$37-Assumptions!$B$38)-((((Historicals!$D$6*(1+Assumptions!$B$26))*(1+Assumptions!$B$27))*(1+Assumptions!$B$28))-((Historicals!$D$6*(1+Assumptions!$B$26))*(1+Assumptions!$B$27)))*Assumptions!$B$39)/(1+$A6)^2.5)+((((((Historicals!$D$6*(1+Assumptions!$B$26))*(1+Assumptions!$B$27))*(1+Assumptions!$B$28))*(1+Assumptions!$B$29))*(Assumptions!$B$35*(1-Assumptions!$B$36)+Assumptions!$B$37-Assumptions!$B$38)-(((((Historicals!$D$6*(1+Assumptions!$B$26))*(1+Assumptions!$B$27))*(1+Assumptions!$B$28))*(1+Assumptions!$B$29))-(((Historicals!$D$6*(1+Assumptions!$B$26))*(1+Assumptions!$B$27))*(1+Assumptions!$B$28)))*Assumptions!$B$39)/(1+$A6)^3.5)+(((((((Historicals!$D$6*(1+Assumptions!$B$26))*(1+Assumptions!$B$27))*(1+Assumptions!$B$28))*(1+Assumptions!$B$29))*(1+Assumptions!$B$30))*(Assumptions!$B$35*(1-Assumptions!$B$36)+Assumptions!$B$37-Assumptions!$B$38)-((((((Historicals!$D$6*(1+Assumptions!$B$26))*(1+Assumptions!$B$27))*(1+Assumptions!$B$28))*(1+Assumptions!$B$29))*(1+Assumptions!$B$30))-((((Historicals!$D$6*(1+Assumptions!$B$26))*(1+Assumptions!$B$27))*(1+Assumptions!$B$28))*(1+Assumptions!$B$29)))*Assumptions!$B$39)/(1+$A6)^4.5)+((((((((Historicals!$D$6*(1+Assumptions!$B$26))*(1+Assumptions!$B$27))*(1+Assumptions!$B$28))*(1+Assumptions!$B$29))*(1+Assumptions!$B$30))*(Assumptions!$B$35*(1-Assumptions!$B$36)+Assumptions!$B$37-Assumptions!$B$38)-((((((Historicals!$D$6*(1+Assumptions!$B$26))*(1+Assumptions!$B$27))*(1+Assumptions!$B$28))*(1+Assumptions!$B$29))*(1+Assumptions!$B$30))-((((Historicals!$D$6*(1+Assumptions!$B$26))*(1+Assumptions!$B$27))*(1+Assumptions!$B$28))*(1+Assumptions!$B$29)))*Assumptions!$B$39)*(1+C$5)/($A6-C$5))/(1+$A6)^4.5))-Assumptions!$B$51)/Assumptions!$B$50 -> 404.14624 | D6: =(((((Historicals!$D$6*(1+Assumptions!$B$26))*(Assumptions!$B$35*(1-Assumptions!$B$36)+Assumptions!$B$37-Assumptions!$B$38)-((Historicals!$D$6*(1+Assumptions!$B$26))-Historicals!$D$6)*Assumptions!$B$39)/(1+$A6)^0.5)+((((Historicals!$D$6*(1+Assumptions!$B$26))*(1+Assumptions!$B$27))*(Assumptions!$B$35*(1-Assumptions!$B$36)+Assumptions!$B$37-Assumptions!$B$38)-(((Historicals!$D$6*(1+Assumptions!$B$26))*(1+Assumptions!$B$27))-(Historicals!$D$6*(1+Assumptions!$B$26)))*Assumptions!$B$39)/(1+$A6)^1.5)+(((((Historicals!$D$6*(1+Assumptions!$B$26))*(1+Assumptions!$B$27))*(1+Assumptions!$B$28))*(Assumptions!$B$35*(1-Assumptions!$B$36)+Assumptions!$B$37-Assumptions!$B$38)-((((Historicals!$D$6*(1+Assumptions!$B$26))*(1+Assumptions!$B$27))*(1+Assumptions!$B$28))-((Historicals!$D$6*(1+Assumptions!$B$26))*(1+Assumptions!$B$27)))*Assumptions!$B$39)/(1+$A6)^2.5)+((((((Historicals!$D$6*(1+Assumptions!$B$26))*(1+Assumptions!$B$27))*(1+Assumptions!$B$28))*(1+Assumptions!$B$29))*(Assumptions!$B$35*(1-Assumptions!$B$36)+Assumptions!$B$37-Assumptions!$B$38)-(((((Historicals!$D$6*(1+Assumptions!$B$26))*(1+Assumptions!$B$27))*(1+Assumptions!$B$28))*(1+Assumptions!$B$29))-(((Historicals!$D$6*(1+Assumptions!$B$26))*(1+Assumptions!$B$27))*(1+Assumptions!$B$28)))*Assumptions!$B$39)/(1+$A6)^3.5)+(((((((Historicals!$D$6*(1+Assumptions!$B$26))*(1+Assumptions!$B$27))*(1+Assumptions!$B$28))*(1+Assumptions!$B$29))*(1+Assumptions!$B$30))*(Assumptions!$B$35*(1-Assumptions!$B$36)+Assumptions!$B$37-Assumptions!$B$38)-((((((Historicals!$D$6*(1+Assumptions!$B$26))*(1+Assumptions!$B$27))*(1+Assumptions!$B$28))*(1+Assumptions!$B$29))*(1+Assumptions!$B$30))-((((Historicals!$D$6*(1+Assumptions!$B$26))*(1+Assumptions!$B$27))*(1+Assumptions!$B$28))*(1+Assumptions!$B$29)))*Assumptions!$B$39)/(1+$A6)^4.5)+((((((((Historicals!$D$6*(1+Assumptions!$B$26))*(1+Assumptions!$B$27))*(1+Assumptions!$B$28))*(1+Assumptions!$B$29))*(1+Assumptions!$B$30))*(Assumptions!$B$35*(1-Assumptions!$B$36)+Assumptions!$B$37-Assumptions!$B$38)-((((((Historicals!$D$6*(1+Assumptions!$B$26))*(1+Assumptions!$B$27))*(1+Assumptions!$B$28))*(1+Assumptions!$B$29))*(1+Assumptions!$B$30))-((((Historicals!$D$6*(1+Assumptions!$B$26))*(1+Assumptions!$B$27))*(1+Assumptions!$B$28))*(1+Assumptions!$B$29)))*Assumptions!$B$39)*(1+D$5)/($A6-D$5))/(1+$A6)^4.5))-Assumptions!$B$51)/Assumptions!$B$50 -> 442.29266 | E6: =(((((Historicals!$D$6*(1+Assumptions!$B$26))*(Assumptions!$B$35*(1-Assumptions!$B$36)+Assumptions!$B$37-Assumptions!$B$38)-((Historicals!$D$6*(1+Assumptions!$B$26))-Historicals!$D$6)*Assumptions!$B$39)/(1+$A6)^0.5)+((((Historicals!$D$6*(1+Assumptions!$B$26))*(1+Assumptions!$B$27))*(Assumptions!$B$35*(1-Assumptions!$B$36)+Assumptions!$B$37-Assumptions!$B$38)-(((Historicals!$D$6*(1+Assumptions!$B$26))*(1+Assumptions!$B$27))-(Historicals!$D$6*(1+Assumptions!$B$26)))*Assumptions!$B$39)/(1+$A6)^1.5)+(((((Historicals!$D$6*(1+Assumptions!$B$26))*(1+Assumptions!$B$27))*(1+Assumptions!$B$28))*(Assumptions!$B$35*(1-Assumptions!$B$36)+Assumptions!$B$37-Assumptions!$B$38)-((((Historicals!$D$6*(1+Assumptions!$B$26))*(1+Assumptions!$B$27))*(1+Assumptions!$B$28))-((Historicals!$D$6*(1+Assumptions!$B$26))*(1+Assumptions!$B$27)))*Assumptions!$B$39)/(1+$A6)^2.5)+((((((Historicals!$D$6*(1+Assumptions!$B$26))*(1+Assumptions!$B$27))*(1+Assumptions!$B$28))*(1+Assumptions!$B$29))*(Assumptions!$B$35*(1-Assumptions!$B$36)+Assumptions!$B$37-Assumptions!$B$38)-(((((Historicals!$D$6*(1+Assumptions!$B$26))*(1+Assumptions!$B$27))*(1+Assumptions!$B$28))*(1+Assumptions!$B$29))-(((Historicals!$D$6*(1+Assumptions!$B$26))*(1+Assumptions!$B$27))*(1+Assumptions!$B$28)))*Assumptions!$B$39)/(1+$A6)^3.5)+(((((((Historicals!$D$6*(1+Assumptions!$B$26))*(1+Assumptions!$B$27))*(1+Assumptions!$B$28))*(1+Assumptions!$B$29))*(1+Assumptions!$B$30))*(Assumptions!$B$35*(1-Assumptions!$B$36)+Assumptions!$B$37-Assumptions!$B$38)-((((((Historicals!$D$6*(1+Assumptions!$B$26))*(1+Assumptions!$B$27))*(1+Assumptions!$B$28))*(1+Assumptions!$B$29))*(1+Assumptions!$B$30))-((((Historicals!$D$6*(1+Assumptions!$B$26))*(1+Assumptions!$B$27))*(1+Assumptions!$B$28))*(1+Assumptions!$B$29)))*Assumptions!$B$39)/(1+$A6)^4.5)+((((((((Historicals!$D$6*(1+Assumptions!$B$26))*(1+Assumptions!$B$27))*(1+Assumptions!$B$28))*(1+Assumptions!$B$29))*(1+Assumptions!$B$30))*(Assumptions!$B$35*(1-Assumptions!$B$36)+Assumptions!$B$37-Assumptions!$B$38)-((((((Historicals!$D$6*(1+Assumptions!$B$26))*(1+Assumptions!$B$27))*(1+Assumptions!$B$28))*(1+Assumptions!$B$29))*(1+Assumptions!$B$30))-((((Historicals!$D$6*(1+Assumptions!$B$26))*(1+Assumptions!$B$27))*(1+Assumptions!$B$28))*(1+Assumptions!$B$29)))*Assumptions!$B$39)*(1+E$5)/($A6-E$5))/(1+$A6)^4.5))-Assumptions!$B$51)/Assumptions!$B$50 -> 489.97569 | F6: =(((((Historicals!$D$6*(1+Assumptions!$B$26))*(Assumptions!$B$35*(1-Assumptions!$B$36)+Assumptions!$B$37-Assumptions!$B$38)-((Historicals!$D$6*(1+Assumptions!$B$26))-Historicals!$D$6)*Assumptions!$B$39)/(1+$A6)^0.5)+((((Historicals!$D$6*(1+Assumptions!$B$26))*(1+Assumptions!$B$27))*(Assumptions!$B$35*(1-Assumptions!$B$36)+Assumptions!$B$37-Assumptions!$B$38)-(((Historicals!$D$6*(1+Assumptions!$B$26))*(1+Assumptions!$B$27))-(Historicals!$D$6*(1+Assumptions!$B$26)))*Assumptions!$B$39)/(1+$A6)^1.5)+(((((Historicals!$D$6*(1+Assumptions!$B$26))*(1+Assumptions!$B$27))*(1+Assumptions!$B$28))*(Assumptions!$B$35*(1-Assumptions!$B$36)+Assumptions!$B$37-Assumptions!$B$38)-((((Historicals!$D$6*(1+Assumptions!$B$26))*(1+Assumptions!$B$27))*(1+Assumptions!$B$28))-((Historicals!$D$6*(1+Assumptions!$B$26))*(1+Assumptions!$B$27)))*Assumptions!$B$39)/(1+$A6)^2.5)+((((((Historicals!$D$6*(1+Assumptions!$B$26))*(1+Assumptions!$B$27))*(1+Assumptions!$B$28))*(1+Assumptions!$B$29))*(Assumptions!$B$35*(1-Assumptions!$B$36)+Assumptions!$B$37-Assumptions!$B$38)-(((((Historicals!$D$6*(1+Assumptions!$B$26))*(1+Assumptions!$B$27))*(1+Assumptions!$B$28))*(1+Assumptions!$B$29))-(((Historicals!$D$6*(1+Assumptions!$B$26))*(1+Assumptions!$B$27))*(1+Assumptions!$B$28)))*Assumptions!$B$39)/(1+$A6)^3.5)+(((((((Historicals!$D$6*(1+Assumptions!$B$26))*(1+Assumptions!$B$27))*(1+Assumptions!$B$28))*(1+Assumptions!$B$29))*(1+Assumptions!$B$30))*(Assumptions!$B$35*(1-Assumptions!$B$36)+Assumptions!$B$37-Assumptions!$B$38)-((((((Historicals!$D$6*(1+Assumptions!$B$26))*(1+Assumptions!$B$27))*(1+Assumptions!$B$28))*(1+Assumptions!$B$29))*(1+Assumptions!$B$30))-((((Historicals!$D$6*(1+Assumptions!$B$26))*(1+Assumptions!$B$27))*(1+Assumptions!$B$28))*(1+Assumptions!$B$29)))*Assumptions!$B$39)/(1+$A6)^4.5)+((((((((Historicals!$D$6*(1+Assumptions!$B$26))*(1+Assumptions!$B$27))*(1+Assumptions!$B$28))*(1+Assumptions!$B$29))*(1+Assumptions!$B$30))*(Assumptions!$B$35*(1-Assumptions!$B$36)+Assumptions!$B$37-Assumptions!$B$38)-((((((Historicals!$D$6*(1+Assumptions!$B$26))*(1+Assumptions!$B$27))*(1+Assumptions!$B$28))*(1+Assumptions!$B$29))*(1+Assumptions!$B$30))-((((Historicals!$D$6*(1+Assumptions!$B$26))*(1+Assumptions!$B$27))*(1+Assumptions!$B$28))*(1+Assumptions!$B$29)))*Assumptions!$B$39)*(1+F$5)/($A6-F$5))/(1+$A6)^4.5))-Assumptions!$B$51)/Assumptions!$B$50 -> 551.28244 | G6: =(((((Historicals!$D$6*(1+Assumptions!$B$26))*(Assumptions!$B$35*(1-Assumptions!$B$36)+Assumptions!$B$37-Assumptions!$B$38)-((Historicals!$D$6*(1+Assumptions!$B$26))-Historicals!$D$6)*Assumptions!$B$39)/(1+$A6)^0.5)+((((Historicals!$D$6*(1+Assumptions!$B$26))*(1+Assumptions!$B$27))*(Assumptions!$B$35*(1-Assumptions!$B$36)+Assumptions!$B$37-Assumptions!$B$38)-(((Historicals!$D$6*(1+Assumptions!$B$26))*(1+Assumptions!$B$27))-(Historicals!$D$6*(1+Assumptions!$B$26)))*Assumptions!$B$39)/(1+$A6)^1.5)+(((((Historicals!$D$6*(1+Assumptions!$B$26))*(1+Assumptions!$B$27))*(1+Assumptions!$B$28))*(Assumptions!$B$35*(1-Assumptions!$B$36)+Assumptions!$B$37-Assumptions!$B$38)-((((Historicals!$D$6*(1+Assumptions!$B$26))*(1+Assumptions!$B$27))*(1+Assumptions!$B$28))-((Historicals!$D$6*(1+Assumptions!$B$26))*(1+Assumptions!$B$27)))*Assumptions!$B$39)/(1+$A6)^2.5)+((((((Historicals!$D$6*(1+Assumptions!$B$26))*(1+Assumptions!$B$27))*(1+Assumptions!$B$28))*(1+Assumptions!$B$29))*(Assumptions!$B$35*(1-Assumptions!$B$36)+Assumptions!$B$37-Assumptions!$B$38)-(((((Historicals!$D$6*(1+Assumptions!$B$26))*(1+Assumptions!$B$27))*(1+Assumptions!$B$28))*(1+Assumptions!$B$29))-(((Historicals!$D$6*(1+Assumptions!$B$26))*(1+Assumptions!$B$27))*(1+Assumptions!$B$28)))*Assumptions!$B$39)/(1+$A6)^3.5)+(((((((Historicals!$D$6*(1+Assumptions!$B$26))*(1+Assumptions!$B$27))*(1+Assumptions!$B$28))*(1+Assumptions!$B$29))*(1+Assumptions!$B$30))*(Assumptions!$B$35*(1-Assumptions!$B$36)+Assumptions!$B$37-Assumptions!$B$38)-((((((Historicals!$D$6*(1+Assumptions!$B$26))*(1+Assumptions!$B$27))*(1+Assumptions!$B$28))*(1+Assumptions!$B$29))*(1+Assumptions!$B$30))-((((Historicals!$D$6*(1+Assumptions!$B$26))*(1+Assumptions!$B$27))*(1+Assumptions!$B$28))*(1+Assumptions!$B$29)))*Assumptions!$B$39)/(1+$A6)^4.5)+((((((((Historicals!$D$6*(1+Assumptions!$B$26))*(1+Assumptions!$B$27))*(1+Assumptions!$B$28))*(1+Assumptions!$B$29))*(1+Assumptions!$B$30))*(Assumptions!$B$35*(1-Assumptions!$B$36)+Assumptions!$B$37-Assumptions!$B$38)-((((((Historicals!$D$6*(1+Assumptions!$B$26))*(1+Assumptions!$B$27))*(1+Assumptions!$B$28))*(1+Assumptions!$B$29))*(1+Assumptions!$B$30))-((((Historicals!$D$6*(1+Assumptions!$B$26))*(1+Assumptions!$B$27))*(1+Assumptions!$B$28))*(1+Assumptions!$B$29)))*Assumptions!$B$39)*(1+G$5)/($A6-G$5))/(1+$A6)^4.5))-Assumptions!$B$51)/Assumptions!$B$50 -> 633.02478 | H6: =(((((Historicals!$D$6*(1+Assumptions!$B$26))*(Assumptions!$B$35*(1-Assumptions!$B$36)+Assumptions!$B$37-Assumptions!$B$38)-((Historicals!$D$6*(1+Assumptions!$B$26))-Historicals!$D$6)*Assumptions!$B$39)/(1+$A6)^0.5)+((((Historicals!$D$6*(1+Assumptions!$B$26))*(1+Assumptions!$B$27))*(Assumptions!$B$35*(1-Assumptions!$B$36)+Assumptions!$B$37-Assumptions!$B$38)-(((Historicals!$D$6*(1+Assumptions!$B$26))*(1+Assumptions!$B$27))-(Historicals!$D$6*(1+Assumptions!$B$26)))*Assumptions!$B$39)/(1+$A6)^1.5)+(((((Historicals!$D$6*(1+Assumptions!$B$26))*(1+Assumptions!$B$27))*(1+Assumptions!$B$28))*(Assumptions!$B$35*(1-Assumptions!$B$36)+Assumptions!$B$37-Assumptions!$B$38)-((((Historicals!$D$6*(1+Assumptions!$B$26))*(1+Assumptions!$B$27))*(1+Assumptions!$B$28))-((Historicals!$D$6*(1+Assumptions!$B$26))*(1+Assumptions!$B$27)))*Assumptions!$B$39)/(1+$A6)^2.5)+((((((Historicals!$D$6*(1+Assumptions!$B$26))*(1+Assumptions!$B$27))*(1+Assumptions!$B$28))*(1+Assumptions!$B$29))*(Assumptions!$B$35*(1-Assumptions!$B$36)+Assumptions!$B$37-Assumptions!$B$38)-(((((Historicals!$D$6*(1+Assumptions!$B$26))*(1+Assumptions!$B$27))*(1+Assumptions!$B$28))*(1+Assumptions!$B$29))-(((Historicals!$D$6*(1+Assumptions!$B$26))*(1+Assumptions!$B$27))*(1+Assumptions!$B$28)))*Assumptions!$B$39)/(1+$A6)^3.5)+(((((((Historicals!$D$6*(1+Assumptions!$B$26))*(1+Assumptions!$B$27))*(1+Assumptions!$B$28))*(1+Assumptions!$B$29))*(1+Assumptions!$B$30))*(Assumptions!$B$35*(1-Assumptions!$B$36)+Assumptions!$B$37-Assumptions!$B$38)-((((((Historicals!$D$6*(1+Assumptions!$B$26))*(1+Assumptions!$B$27))*(1+Assumptions!$B$28))*(1+Assumptions!$B$29))*(1+Assumptions!$B$30))-((((Historicals!$D$6*(1+Assumptions!$B$26))*(1+Assumptions!$B$27))*(1+Assumptions!$B$28))*(1+Assumptions!$B$29)))*Assumptions!$B$39)/(1+$A6)^4.5)+((((((((Historicals!$D$6*(1+Assumptions!$B$26))*(1+Assumptions!$B$27))*(1+Assumptions!$B$28))*(1+Assumptions!$B$29))*(1+Assumptions!$B$30))*(Assumptions!$B$35*(1-Assumptions!$B$36)+Assumptions!$B$37-Assumptions!$B$38)-((((((Historicals!$D$6*(1+Assumptions!$B$26))*(1+Assumptions!$B$27))*(1+Assumptions!$B$28))*(1+Assumptions!$B$29))*(1+Assumptions!$B$30))-((((Historicals!$D$6*(1+Assumptions!$B$26))*(1+Assumptions!$B$27))*(1+Assumptions!$B$28))*(1+Assumptions!$B$29)))*Assumptions!$B$39)*(1+H$5)/($A6-H$5))/(1+$A6)^4.5))-Assumptions!$B$51)/Assumptions!$B$50 -> 747.46405
A7: 0.075 | B7: =(((((Historicals!$D$6*(1+Assumptions!$B$26))*(Assumptions!$B$35*(1-Assumptions!$B$36)+Assumptions!$B$37-Assumptions!$B$38)-((Historicals!$D$6*(1+Assumptions!$B$26))-Historicals!$D$6)*Assumptions!$B$39)/(1+$A7)^0.5)+((((Historicals!$D$6*(1+Assumptions!$B$26))*(1+Assumptions!$B$27))*(Assumptions!$B$35*(1-Assumptions!$B$36)+Assumptions!$B$37-Assumptions!$B$38)-(((Historicals!$D$6*(1+Assumptions!$B$26))*(1+Assumptions!$B$27))-(Historicals!$D$6*(1+Assumptions!$B$26)))*Assumptions!$B$39)/(1+$A7)^1.5)+(((((Historicals!$D$6*(1+Assumptions!$B$26))*(1+Assumptions!$B$27))*(1+Assumptions!$B$28))*(Assumptions!$B$35*(1-Assumptions!$B$36)+Assumptions!$B$37-Assumptions!$B$38)-((((Historicals!$D$6*(1+Assumptions!$B$26))*(1+Assumptions!$B$27))*(1+Assumptions!$B$28))-((Historicals!$D$6*(1+Assumptions!$B$26))*(1+Assumptions!$B$27)))*Assumptions!$B$39)/(1+$A7)^2.5)+((((((Historicals!$D$6*(1+Assumptions!$B$26))*(1+Assumptions!$B$27))*(1+Assumptions!$B$28))*(1+Assumptions!$B$29))*(Assumptions!$B$35*(1-Assumptions!$B$36)+Assumptions!$B$37-Assumptions!$B$38)-(((((Historicals!$D$6*(1+Assumptions!$B$26))*(1+Assumptions!$B$27))*(1+Assumptions!$B$28))*(1+Assumptions!$B$29))-(((Historicals!$D$6*(1+Assumptions!$B$26))*(1+Assumptions!$B$27))*(1+Assumptions!$B$28)))*Assumptions!$B$39)/(1+$A7)^3.5)+(((((((Historicals!$D$6*(1+Assumptions!$B$26))*(1+Assumptions!$B$27))*(1+Assumptions!$B$28))*(1+Assumptions!$B$29))*(1+Assumptions!$B$30))*(Assumptions!$B$35*(1-Assumptions!$B$36)+Assumptions!$B$37-Assumptions!$B$38)-((((((Historicals!$D$6*(1+Assumptions!$B$26))*(1+Assumptions!$B$27))*(1+Assumptions!$B$28))*(1+Assumptions!$B$29))*(1+Assumptions!$B$30))-((((Historicals!$D$6*(1+Assumptions!$B$26))*(1+Assumptions!$B$27))*(1+Assumptions!$B$28))*(1+Assumptions!$B$29)))*Assumptions!$B$39)/(1+$A7)^4.5)+((((((((Historicals!$D$6*(1+Assumptions!$B$26))*(1+Assumptions!$B$27))*(1+Assumptions!$B$28))*(1+Assumptions!$B$29))*(1+Assumptions!$B$30))*(Assumptions!$B$35*(1-Assumptions!$B$36)+Assumptions!$B$37-Assumptions!$B$38)-((((((Historicals!$D$6*(1+Assumptions!$B$26))*(1+Assumptions!$B$27))*(1+Assumptions!$B$28))*(1+Assumptions!$B$29))*(1+Assumptions!$B$30))-((((Historicals!$D$6*(1+Assumptions!$B$26))*(1+Assumptions!$B$27))*(1+Assumptions!$B$28))*(1+Assumptions!$B$29)))*Assumptions!$B$39)*(1+B$5)/($A7-B$5))/(1+$A7)^4.5))-Assumptions!$B$51)/Assumptions!$B$50 -> 341.74688 | C7: =(((((Historicals!$D$6*(1+Assumptions!$B$26))*(Assumptions!$B$35*(1-Assumptions!$B$36)+Assumptions!$B$37-Assumptions!$B$38)-((Historicals!$D$6*(1+Assumptions!$B$26))-Historicals!$D$6)*Assumptions!$B$39)/(1+$A7)^0.5)+((((Historicals!$D$6*(1+Assumptions!$B$26))*(1+Assumptions!$B$27))*(Assumptions!$B$35*(1-Assumptions!$B$36)+Assumptions!$B$37-Assumptions!$B$38)-(((Historicals!$D$6*(1+Assumptions!$B$26))*(1+Assumptions!$B$27))-(Historicals!$D$6*(1+Assumptions!$B$26)))*Assumptions!$B$39)/(1+$A7)^1.5)+(((((Historicals!$D$6*(1+Assumptions!$B$26))*(1+Assumptions!$B$27))*(1+Assumptions!$B$28))*(Assumptions!$B$35*(1-Assumptions!$B$36)+Assumptions!$B$37-Assumptions!$B$38)-((((Historicals!$D$6*(1+Assumptions!$B$26))*(1+Assumptions!$B$27))*(1+Assumptions!$B$28))-((Historicals!$D$6*(1+Assumptions!$B$26))*(1+Assumptions!$B$27)))*Assumptions!$B$39)/(1+$A7)^2.5)+((((((Historicals!$D$6*(1+Assumptions!$B$26))*(1+Assumptions!$B$27))*(1+Assumptions!$B$28))*(1+Assumptions!$B$29))*(Assumptions!$B$35*(1-Assumptions!$B$36)+Assumptions!$B$37-Assumptions!$B$38)-(((((Historicals!$D$6*(1+Assumptions!$B$26))*(1+Assumptions!$B$27))*(1+Assumptions!$B$28))*(1+Assumptions!$B$29))-(((Historicals!$D$6*(1+Assumptions!$B$26))*(1+Assumptions!$B$27))*(1+Assumptions!$B$28)))*Assumptions!$B$39)/(1+$A7)^3.5)+(((((((Historicals!$D$6*(1+Assumptions!$B$26))*(1+Assumptions!$B$27))*(1+Assumptions!$B$28))*(1+Assumptions!$B$29))*(1+Assumptions!$B$30))*(Assumptions!$B$35*(1-Assumptions!$B$36)+Assumptions!$B$37-Assumptions!$B$38)-((((((Historicals!$D$6*(1+Assumptions!$B$26))*(1+Assumptions!$B$27))*(1+Assumptions!$B$28))*(1+Assumptions!$B$29))*(1+Assumptions!$B$30))-((((Historicals!$D$6*(1+Assumptions!$B$26))*(1+Assumptions!$B$27))*(1+Assumptions!$B$28))*(1+Assumptions!$B$29)))*Assumptions!$B$39)/(1+$A7)^4.5)+((((((((Historicals!$D$6*(1+Assumptions!$B$26))*(1+Assumptions!$B$27))*(1+Assumptions!$B$28))*(1+Assumptions!$B$29))*(1+Assumptions!$B$30))*(Assumptions!$B$35*(1-Assumptions!$B$36)+Assumptions!$B$37-Assumptions!$B$38)-((((((Historicals!$D$6*(1+Assumptions!$B$26))*(1+Assumptions!$B$27))*(1+Assumptions!$B$28))*(1+Assumptions!$B$29))*(1+Assumptions!$B$30))-((((Historicals!$D$6*(1+Assumptions!$B$26))*(1+Assumptions!$B$27))*(1+Assumptions!$B$28))*(1+Assumptions!$B$29)))*Assumptions!$B$39)*(1+C$5)/($A7-C$5))/(1+$A7)^4.5))-Assumptions!$B$51)/Assumptions!$B$50 -> 367.33486 | D7: =(((((Historicals!$D$6*(1+Assumptions!$B$26))*(Assumptions!$B$35*(1-Assumptions!$B$36)+Assumptions!$B$37-Assumptions!$B$38)-((Historicals!$D$6*(1+Assumptions!$B$26))-Historicals!$D$6)*Assumptions!$B$39)/(1+$A7)^0.5)+((((Historicals!$D$6*(1+Assumptions!$B$26))*(1+Assumptions!$B$27))*(Assumptions!$B$35*(1-Assumptions!$B$36)+Assumptions!$B$37-Assumptions!$B$38)-(((Historicals!$D$6*(1+Assumptions!$B$26))*(1+Assumptions!$B$27))-(Historicals!$D$6*(1+Assumptions!$B$26)))*Assumptions!$B$39)/(1+$A7)^1.5)+(((((Historicals!$D$6*(1+Assumptions!$B$26))*(1+Assumptions!$B$27))*(1+Assumptions!$B$28))*(Assumptions!$B$35*(1-Assumptions!$B$36)+Assumptions!$B$37-Assumptions!$B$38)-((((Historicals!$D$6*(1+Assumptions!$B$26))*(1+Assumptions!$B$27))*(1+Assumptions!$B$28))-((Historicals!$D$6*(1+Assumptions!$B$26))*(1+Assumptions!$B$27)))*Assumptions!$B$39)/(1+$A7)^2.5)+((((((Historicals!$D$6*(1+Assumptions!$B$26))*(1+Assumptions!$B$27))*(1+Assumptions!$B$28))*(1+Assumptions!$B$29))*(Assumptions!$B$35*(1-Assumptions!$B$36)+Assumptions!$B$37-Assumptions!$B$38)-(((((Historicals!$D$6*(1+Assumptions!$B$26))*(1+Assumptions!$B$27))*(1+Assumptions!$B$28))*(1+Assumptions!$B$29))-(((Historicals!$D$6*(1+Assumptions!$B$26))*(1+Assumptions!$B$27))*(1+Assumptions!$B$28)))*Assumptions!$B$39)/(1+$A7)^3.5)+(((((((Historicals!$D$6*(1+Assumptions!$B$26))*(1+Assumptions!$B$27))*(1+Assumptions!$B$28))*(1+Assumptions!$B$29))*(1+Assumptions!$B$30))*(Assumptions!$B$35*(1-Assumptions!$B$36)+Assumptions!$B$37-Assumptions!$B$38)-((((((Historicals!$D$6*(1+Assumptions!$B$26))*(1+Assumptions!$B$27))*(1+Assumptions!$B$28))*(1+Assumptions!$B$29))*(1+Assumptions!$B$30))-((((Historicals!$D$6*(1+Assumptions!$B$26))*(1+Assumptions!$B$27))*(1+Assumptions!$B$28))*(1+Assumptions!$B$29)))*Assumptions!$B$39)/(1+$A7)^4.5)+((((((((Historicals!$D$6*(1+Assumptions!$B$26))*(1+Assumptions!$B$27))*(1+Assumptions!$B$28))*(1+Assumptions!$B$29))*(1+Assumptions!$B$30))*(Assumptions!$B$35*(1-Assumptions!$B$36)+Assumptions!$B$37-Assumptions!$B$38)-((((((Historicals!$D$6*(1+Assumptions!$B$26))*(1+Assumptions!$B$27))*(1+Assumptions!$B$28))*(1+Assumptions!$B$29))*(1+Assumptions!$B$30))-((((Historicals!$D$6*(1+Assumptions!$B$26))*(1+Assumptions!$B$27))*(1+Assumptions!$B$28))*(1+Assumptions!$B$29)))*Assumptions!$B$39)*(1+D$5)/($A7-D$5))/(1+$A7)^4.5))-Assumptions!$B$51)/Assumptions!$B$50 -> 398.04043 | E7: =(((((Historicals!$D$6*(1+Assumptions!$B$26))*(Assumptions!$B$35*(1-Assumptions!$B$36)+Assumptions!$B$37-Assumptions!$B$38)-((Historicals!$D$6*(1+Assumptions!$B$26))-Historicals!$D$6)*Assumptions!$B$39)/(1+$A7)^0.5)+((((Historicals!$D$6*(1+Assumptions!$B$26))*(1+Assumptions!$B$27))*(Assumptions!$B$35*(1-Assumptions!$B$36)+Assumptions!$B$37-Assumptions!$B$38)-(((Historicals!$D$6*(1+Assumptions!$B$26))*(1+Assumptions!$B$27))-(Historicals!$D$6*(1+Assumptions!$B$26)))*Assumptions!$B$39)/(1+$A7)^1.5)+(((((Historicals!$D$6*(1+Assumptions!$B$26))*(1+Assumptions!$B$27))*(1+Assumptions!$B$28))*(Assumptions!$B$35*(1-Assumptions!$B$36)+Assumptions!$B$37-Assumptions!$B$38)-((((Historicals!$D$6*(1+Assumptions!$B$26))*(1+Assumptions!$B$27))*(1+Assumptions!$B$28))-((Historicals!$D$6*(1+Assumptions!$B$26))*(1+Assumptions!$B$27)))*Assumptions!$B$39)/(1+$A7)^2.5)+((((((Historicals!$D$6*(1+Assumptions!$B$26))*(1+Assumptions!$B$27))*(1+Assumptions!$B$28))*(1+Assumptions!$B$29))*(Assumptions!$B$35*(1-Assumptions!$B$36)+Assumptions!$B$37-Assumptions!$B$38)-(((((Historicals!$D$6*(1+Assumptions!$B$26))*(1+Assumptions!$B$27))*(1+Assumptions!$B$28))*(1+Assumptions!$B$29))-(((Historicals!$D$6*(1+Assumptions!$B$26))*(1+Assumptions!$B$27))*(1+Assumptions!$B$28)))*Assumptions!$B$39)/(1+$A7)^3.5)+(((((((Historicals!$D$6*(1+Assumptions!$B$26))*(1+Assumptions!$B$27))*(1+Assumptions!$B$28))*(1+Assumptions!$B$29))*(1+Assumptions!$B$30))*(Assumptions!$B$35*(1-Assumptions!$B$36)+Assumptions!$B$37-Assumptions!$B$38)-((((((Historicals!$D$6*(1+Assumptions!$B$26))*(1+Assumptions!$B$27))*(1+Assumptions!$B$28))*(1+Assumptions!$B$29))*(1+Assumptions!$B$30))-((((Historicals!$D$6*(1+Assumptions!$B$26))*(1+Assumptions!$B$27))*(1+Assumptions!$B$28))*(1+Assumptions!$B$29)))*Assumptions!$B$39)/(1+$A7)^4.5)+((((((((Historicals!$D$6*(1+Assumptions!$B$26))*(1+Assumptions!$B$27))*(1+Assumptions!$B$28))*(1+Assumptions!$B$29))*(1+Assumptions!$B$30))*(Assumptions!$B$35*(1-Assumptions!$B$36)+Assumptions!$B$37-Assumptions!$B$38)-((((((Historicals!$D$6*(1+Assumptions!$B$26))*(1+Assumptions!$B$27))*(1+Assumptions!$B$28))*(1+Assumptions!$B$29))*(1+Assumptions!$B$30))-((((Historicals!$D$6*(1+Assumptions!$B$26))*(1+Assumptions!$B$27))*(1+Assumptions!$B$28))*(1+Assumptions!$B$29)))*Assumptions!$B$39)*(1+E$5)/($A7-E$5))/(1+$A7)^4.5))-Assumptions!$B$51)/Assumptions!$B$50 -> 435.56947 | F7: =(((((Historicals!$D$6*(1+Assumptions!$B$26))*(Assumptions!$B$35*(1-Assumptions!$B$36)+Assumptions!$B$37-Assumptions!$B$38)-((Historicals!$D$6*(1+Assumptions!$B$26))-Historicals!$D$6)*Assumptions!$B$39)/(1+$A7)^0.5)+((((Historicals!$D$6*(1+Assumptions!$B$26))*(1+Assumptions!$B$27))*(Assumptions!$B$35*(1-Assumptions!$B$36)+Assumptions!$B$37-Assumptions!$B$38)-(((Historicals!$D$6*(1+Assumptions!$B$26))*(1+Assumptions!$B$27))-(Historicals!$D$6*(1+Assumptions!$B$26)))*Assumptions!$B$39)/(1+$A7)^1.5)+(((((Historicals!$D$6*(1+Assumptions!$B$26))*(1+Assumptions!$B$27))*(1+Assumptions!$B$28))*(Assumptions!$B$35*(1-Assumptions!$B$36)+Assumptions!$B$37-Assumptions!$B$38)-((((Historicals!$D$6*(1+Assumptions!$B$26))*(1+Assumptions!$B$27))*(1+Assumptions!$B$28))-((Historicals!$D$6*(1+Assumptions!$B$26))*(1+Assumptions!$B$27)))*Assumptions!$B$39)/(1+$A7)^2.5)+((((((Historicals!$D$6*(1+Assumptions!$B$26))*(1+Assumptions!$B$27))*(1+Assumptions!$B$28))*(1+Assumptions!$B$29))*(Assumptions!$B$35*(1-Assumptions!$B$36)+Assumptions!$B$37-Assumptions!$B$38)-(((((Historicals!$D$6*(1+Assumptions!$B$26))*(1+Assumptions!$B$27))*(1+Assumptions!$B$28))*(1+Assumptions!$B$29))-(((Historicals!$D$6*(1+Assumptions!$B$26))*(1+Assumptions!$B$27))*(1+Assumptions!$B$28)))*Assumptions!$B$39)/(1+$A7)^3.5)+(((((((Historicals!$D$6*(1+Assumptions!$B$26))*(1+Assumptions!$B$27))*(1+Assumptions!$B$28))*(1+Assumptions!$B$29))*(1+Assumptions!$B$30))*(Assumptions!$B$35*(1-Assumptions!$B$36)+Assumptions!$B$37-Assumptions!$B$38)-((((((Historicals!$D$6*(1+Assumptions!$B$26))*(1+Assumptions!$B$27))*(1+Assumptions!$B$28))*(1+Assumptions!$B$29))*(1+Assumptions!$B$30))-((((Historicals!$D$6*(1+Assumptions!$B$26))*(1+Assumptions!$B$27))*(1+Assumptions!$B$28))*(1+Assumptions!$B$29)))*Assumptions!$B$39)/(1+$A7)^4.5)+((((((((Historicals!$D$6*(1+Assumptions!$B$26))*(1+Assumptions!$B$27))*(1+Assumptions!$B$28))*(1+Assumptions!$B$29))*(1+Assumptions!$B$30))*(Assumptions!$B$35*(1-Assumptions!$B$36)+Assumptions!$B$37-Assumptions!$B$38)-((((((Historicals!$D$6*(1+Assumptions!$B$26))*(1+Assumptions!$B$27))*(1+Assumptions!$B$28))*(1+Assumptions!$B$29))*(1+Assumptions!$B$30))-((((Historicals!$D$6*(1+Assumptions!$B$26))*(1+Assumptions!$B$27))*(1+Assumptions!$B$28))*(1+Assumptions!$B$29)))*Assumptions!$B$39)*(1+F$5)/($A7-F$5))/(1+$A7)^4.5))-Assumptions!$B$51)/Assumptions!$B$50 -> 482.48077 | G7: =(((((Historicals!$D$6*(1+Assumptions!$B$26))*(Assumptions!$B$35*(1-Assumptions!$B$36)+Assumptions!$B$37-Assumptions!$B$38)-((Historicals!$D$6*(1+Assumptions!$B$26))-Historicals!$D$6)*Assumptions!$B$39)/(1+$A7)^0.5)+((((Historicals!$D$6*(1+Assumptions!$B$26))*(1+Assumptions!$B$27))*(Assumptions!$B$35*(1-Assumptions!$B$36)+Assumptions!$B$37-Assumptions!$B$38)-(((Historicals!$D$6*(1+Assumptions!$B$26))*(1+Assumptions!$B$27))-(Historicals!$D$6*(1+Assumptions!$B$26)))*Assumptions!$B$39)/(1+$A7)^1.5)+(((((Historicals!$D$6*(1+Assumptions!$B$26))*(1+Assumptions!$B$27))*(1+Assumptions!$B$28))*(Assumptions!$B$35*(1-Assumptions!$B$36)+Assumptions!$B$37-Assumptions!$B$38)-((((Historicals!$D$6*(1+Assumptions!$B$26))*(1+Assumptions!$B$27))*(1+Assumptions!$B$28))-((Historicals!$D$6*(1+Assumptions!$B$26))*(1+Assumptions!$B$27)))*Assumptions!$B$39)/(1+$A7)^2.5)+((((((Historicals!$D$6*(1+Assumptions!$B$26))*(1+Assumptions!$B$27))*(1+Assumptions!$B$28))*(1+Assumptions!$B$29))*(Assumptions!$B$35*(1-Assumptions!$B$36)+Assumptions!$B$37-Assumptions!$B$38)-(((((Historicals!$D$6*(1+Assumptions!$B$26))*(1+Assumptions!$B$27))*(1+Assumptions!$B$28))*(1+Assumptions!$B$29))-(((Historicals!$D$6*(1+Assumptions!$B$26))*(1+Assumptions!$B$27))*(1+Assumptions!$B$28)))*Assumptions!$B$39)/(1+$A7)^3.5)+(((((((Historicals!$D$6*(1+Assumptions!$B$26))*(1+Assumptions!$B$27))*(1+Assumptions!$B$28))*(1+Assumptions!$B$29))*(1+Assumptions!$B$30))*(Assumptions!$B$35*(1-Assumptions!$B$36)+Assumptions!$B$37-Assumptions!$B$38)-((((((Historicals!$D$6*(1+Assumptions!$B$26))*(1+Assumptions!$B$27))*(1+Assumptions!$B$28))*(1+Assumptions!$B$29))*(1+Assumptions!$B$30))-((((Historicals!$D$6*(1+Assumptions!$B$26))*(1+Assumptions!$B$27))*(1+Assumptions!$B$28))*(1+Assumptions!$B$29)))*Assumptions!$B$39)/(1+$A7)^4.5)+((((((((Historicals!$D$6*(1+Assumptions!$B$26))*(1+Assumptions!$B$27))*(1+Assumptions!$B$28))*(1+Assumptions!$B$29))*(1+Assumptions!$B$30))*(Assumptions!$B$35*(1-Assumptions!$B$36)+Assumptions!$B$37-Assumptions!$B$38)-((((((Historicals!$D$6*(1+Assumptions!$B$26))*(1+Assumptions!$B$27))*(1+Assumptions!$B$28))*(1+Assumptions!$B$29))*(1+Assumptions!$B$30))-((((Historicals!$D$6*(1+Assumptions!$B$26))*(1+Assumptions!$B$27))*(1+Assumptions!$B$28))*(1+Assumptions!$B$29)))*Assumptions!$B$39)*(1+G$5)/($A7-G$5))/(1+$A7)^4.5))-Assumptions!$B$51)/Assumptions!$B$50 -> 542.79529 | H7: =(((((Historicals!$D$6*(1+Assumptions!$B$26))*(Assumptions!$B$35*(1-Assumptions!$B$36)+Assumptions!$B$37-Assumptions!$B$38)-((Historicals!$D$6*(1+Assumptions!$B$26))-Historicals!$D$6)*Assumptions!$B$39)/(1+$A7)^0.5)+((((Historicals!$D$6*(1+Assumptions!$B$26))*(1+Assumptions!$B$27))*(Assumptions!$B$35*(1-Assumptions!$B$36)+Assumptions!$B$37-Assumptions!$B$38)-(((Historicals!$D$6*(1+Assumptions!$B$26))*(1+Assumptions!$B$27))-(Historicals!$D$6*(1+Assumptions!$B$26)))*Assumptions!$B$39)/(1+$A7)^1.5)+(((((Historicals!$D$6*(1+Assumptions!$B$26))*(1+Assumptions!$B$27))*(1+Assumptions!$B$28))*(Assumptions!$B$35*(1-Assumptions!$B$36)+Assumptions!$B$37-Assumptions!$B$38)-((((Historicals!$D$6*(1+Assumptions!$B$26))*(1+Assumptions!$B$27))*(1+Assumptions!$B$28))-((Historicals!$D$6*(1+Assumptions!$B$26))*(1+Assumptions!$B$27)))*Assumptions!$B$39)/(1+$A7)^2.5)+((((((Historicals!$D$6*(1+Assumptions!$B$26))*(1+Assumptions!$B$27))*(1+Assumptions!$B$28))*(1+Assumptions!$B$29))*(Assumptions!$B$35*(1-Assumptions!$B$36)+Assumptions!$B$37-Assumptions!$B$38)-(((((Historicals!$D$6*(1+Assumptions!$B$26))*(1+Assumptions!$B$27))*(1+Assumptions!$B$28))*(1+Assumptions!$B$29))-(((Historicals!$D$6*(1+Assumptions!$B$26))*(1+Assumptions!$B$27))*(1+Assumptions!$B$28)))*Assumptions!$B$39)/(1+$A7)^3.5)+(((((((Historicals!$D$6*(1+Assumptions!$B$26))*(1+Assumptions!$B$27))*(1+Assumptions!$B$28))*(1+Assumptions!$B$29))*(1+Assumptions!$B$30))*(Assumptions!$B$35*(1-Assumptions!$B$36)+Assumptions!$B$37-Assumptions!$B$38)-((((((Historicals!$D$6*(1+Assumptions!$B$26))*(1+Assumptions!$B$27))*(1+Assumptions!$B$28))*(1+Assumptions!$B$29))*(1+Assumptions!$B$30))-((((Historicals!$D$6*(1+Assumptions!$B$26))*(1+Assumptions!$B$27))*(1+Assumptions!$B$28))*(1+Assumptions!$B$29)))*Assumptions!$B$39)/(1+$A7)^4.5)+((((((((Historicals!$D$6*(1+Assumptions!$B$26))*(1+Assumptions!$B$27))*(1+Assumptions!$B$28))*(1+Assumptions!$B$29))*(1+Assumptions!$B$30))*(Assumptions!$B$35*(1-Assumptions!$B$36)+Assumptions!$B$37-Assumptions!$B$38)-((((((Historicals!$D$6*(1+Assumptions!$B$26))*(1+Assumptions!$B$27))*(1+Assumptions!$B$28))*(1+Assumptions!$B$29))*(1+Assumptions!$B$30))-((((Historicals!$D$6*(1+Assumptions!$B$26))*(1+Assumptions!$B$27))*(1+Assumptions!$B$28))*(1+Assumptions!$B$29)))*Assumptions!$B$39)*(1+H$5)/($A7-H$5))/(1+$A7)^4.5))-Assumptions!$B$51)/Assumptions!$B$50 -> 623.21466
